<?xml version='1.0' encoding='utf-8'?>
<robot name="V0.01">
    <link name="1-clamp">
        <inertial>
            <origin xyz="-0.01011633177640657 0.01995 0.012349999999998097" rpy="0.0 0.0 0.0" />
            <mass value="0.09978554550837347" />
            <inertia ixx="2.8952195540493082e-05" iyy="4.515825456914321e-05" izz="2.8802758876856415e-05" ixy="-3.3881317890172014e-21" iyz="3.3881317890172014e-21" ixz="4.6095532989579024e-18" />
        </inertial>
        <visual name="1-clamp_visual">
            <origin xyz="0.0 0.0 0.0" rpy="0.0 0.0 0.0" />
            <geometry>
                <mesh filename="meshes/1-clamp.stl" scale="0.001 0.001 0.001" />
            </geometry>
        </visual>
        <collision name="1-clamp_collision">
            <origin xyz="0.0 0.0 0.0" rpy="0.0 0.0 0.0" />
            <geometry>
                <mesh filename="meshes/1-clamp.stl" scale="0.001 0.001 0.001" />
            </geometry>
        </collision>
    </link>
    <link name="1-servo">
        <inertial>
            <origin xyz="0.022668652600844448 0.013384817444929977 0.0" rpy="0.0 -0.0 0.0" />
            <mass value="0.3033412377430849" />
            <inertia ixx="4.4115613291432376e-05" iyy="6.884216194152031e-05" izz="8.178619368144822e-05" ixy="-9.243992458147531e-07" iyz="0.0" ixz="1.3552527156068805e-20" />
        </inertial>
        <visual name="1-servo_visual">
            <origin xyz="0.0275 0.03395 0.012350000000000002" rpy="3.141592653589793 -0.0 0.0" />
            <geometry>
                <mesh filename="meshes/1-servo.stl" scale="0.001 0.001 0.001" />
            </geometry>
        </visual>
        <collision name="1-servo_collision">
            <origin xyz="0.0275 0.03395 0.012350000000000002" rpy="3.141592653589793 -0.0 0.0" />
            <geometry>
                <mesh filename="meshes/1-servo.stl" scale="0.001 0.001 0.001" />
            </geometry>
        </collision>
    </link>
    <link name="3-clamp">
        <inertial>
            <origin xyz="0.026616328864181887 -0.025350002912221684 -3.9968028886505636e-16" rpy="0.0 -0.0 0.0" />
            <mass value="0.09978554550837337" />
            <inertia ixx="2.8952195540500082e-05" iyy="2.8802758876854575e-05" izz="4.515825456909064e-05" ixy="-3.333921680392926e-18" iyz="-1.1763593571467723e-17" ixz="6.037650848028653e-18" />
        </inertial>
        <visual name="3-clamp_visual">
            <origin xyz="-0.10805000291222866 -0.20816977708777668 -0.010500000447035276" rpy="7.771561172375865e-16 -2.113062989360782e-15 -1.5707963267948921" />
            <geometry>
                <mesh filename="meshes/3-clamp.stl" scale="0.001 0.001 0.001" />
            </geometry>
        </visual>
        <collision name="3-clamp_collision">
            <origin xyz="-0.10805000291222866 -0.20816977708777668 -0.010500000447035276" rpy="7.771561172375865e-16 -2.113062989360782e-15 -1.5707963267948921" />
            <geometry>
                <mesh filename="meshes/3-clamp.stl" scale="0.001 0.001 0.001" />
            </geometry>
        </collision>
    </link>
    <link name="3-holder">
        <inertial>
            <origin xyz="0.004904846659727005 0.08187908906454737 -0.01780984914393404" rpy="0.0 -0.0 0.0" />
            <mass value="0.6053159680782471" />
            <inertia ixx="0.0017174592546749384" iyy="0.00018649161391586877" izz="0.0017005174574323996" ixy="-0.00017713765140459125" iyz="9.229700061045416e-06" ixz="1.9297077568748627e-06" />
        </inertial>
        <visual name="3-holder_visual">
            <origin xyz="-0.0838348929122288 -0.041584887087776516 -0.02845000044703527" rpy="8.881784197000973e-16 -2.3496457565353582e-15 -1.5707963267948923" />
            <geometry>
                <mesh filename="meshes/3-holder.stl" scale="0.001 0.001 0.001" />
            </geometry>
        </visual>
        <collision name="3-holder_collision">
            <origin xyz="-0.0838348929122288 -0.041584887087776516 -0.02845000044703527" rpy="8.881784197000973e-16 -2.3496457565353582e-15 -1.5707963267948923" />
            <geometry>
                <mesh filename="meshes/3-holder.stl" scale="0.001 0.001 0.001" />
            </geometry>
        </collision>
    </link>
    <link name="4-clamp">
        <inertial>
            <origin xyz="0.02661633177641333 -0.02534999865889823 -2.2351743567128325e-10" rpy="0.0 -0.0 0.0" />
            <mass value="0.09978554550837349" />
            <inertia ixx="2.8952195540538246e-05" iyy="2.8802758876845993e-05" izz="4.5158254569134006e-05" ixy="2.2985086056692694e-17" iyz="-4.445228907190568e-18" ixz="-5.366800753803247e-18" />
        </inertial>
        <visual name="4-clamp_visual">
            <origin xyz="0.06296977417555906 0.1142500013411045 0.01055000022351817" rpy="-3.1415926535897896 2.886579864025275e-15 2.9999587652126956e-15" />
            <geometry>
                <mesh filename="meshes/4-clamp.stl" scale="0.001 0.001 0.001" />
            </geometry>
        </visual>
        <collision name="4-clamp_collision">
            <origin xyz="0.06296977417555906 0.1142500013411045 0.01055000022351817" rpy="-3.1415926535897896 2.886579864025275e-15 2.9999587652126956e-15" />
            <geometry>
                <mesh filename="meshes/4-clamp.stl" scale="0.001 0.001 0.001" />
            </geometry>
        </collision>
    </link>
    <link name="4-holder">
        <inertial>
            <origin xyz="0.06444860833955965 -0.00012847069117800203 -0.01774705175856157" rpy="0.0 -0.0 0.0" />
            <mass value="0.47983450816069384" />
            <inertia ixx="0.00012625064179755396" iyy="0.0010110873650053336" izz="0.0009404225454982436" ixy="3.6568094264055623e-06" iyz="-2.9105058382496587e-08" ixz="8.13322214573731e-06" />
        </inertial>
        <visual name="4-holder_visual">
            <origin xyz="0.1830848841755587 -0.14033489134110486 -0.028450000223518124" rpy="1.2722154311270206e-15 -1.2767564783188772e-15 -3.4995483853165215e-15" />
            <geometry>
                <mesh filename="meshes/4-holder.stl" scale="0.001 0.001 0.001" />
            </geometry>
        </visual>
        <collision name="4-holder_collision">
            <origin xyz="0.1830848841755587 -0.14033489134110486 -0.028450000223518124" rpy="1.2722154311270206e-15 -1.2767564783188772e-15 -3.4995483853165215e-15" />
            <geometry>
                <mesh filename="meshes/4-holder.stl" scale="0.001 0.001 0.001" />
            </geometry>
        </collision>
    </link>
    <link name="3-servo">
        <inertial>
            <origin xyz="0.013384817444929656 -2.9122199052267207e-09 0.022668655513069274" rpy="4.39573844726499e-93 -0.0 0.0" />
            <mass value="0.30334123774308486" />
            <inertia ixx="6.884216194145455e-05" iyy="8.178619368146925e-05" izz="4.411561329151388e-05" ixy="-3.8272336688738307e-17" iyz="3.7513395167998453e-17" ixz="-9.243992458164234e-07" />
        </inertial>
        <visual name="3-servo_visual">
            <origin xyz="0.0023499999999997347 -0.1829500029122266 0.14680000291222847" rpy="-1.570796326794897 5.021645928919806e-15 -1.5707963267948946" />
            <geometry>
                <mesh filename="meshes/3-servo.stl" scale="0.001 0.001 0.001" />
            </geometry>
        </visual>
        <collision name="3-servo_collision">
            <origin xyz="0.0023499999999997347 -0.1829500029122266 0.14680000291222847" rpy="-1.570796326794897 5.021645928919806e-15 -1.5707963267948946" />
            <geometry>
                <mesh filename="meshes/3-servo.stl" scale="0.001 0.001 0.001" />
            </geometry>
        </collision>
    </link>
    <link name="2-clamp">
        <inertial>
            <origin xyz="0.02534999551665167 0.026616331776406554 -2.2351748674154237e-10" rpy="0.0 -0.0 5.300260399008595e-96" />
            <mass value="0.09978554550837361" />
            <inertia ixx="2.8802758876891204e-05" iyy="2.895219554048233e-05" izz="4.5158254569179325e-05" ixy="-4.87890977618477e-18" iyz="-1.3552527156068805e-20" ixz="1.4907779871675686e-19" />
        </inertial>
        <visual name="2-clamp_visual">
            <origin xyz="0.06839999551665468 -0.05204999999999996 -0.012000000223517826" rpy="-7.855721281318744e-17 8.881784197001016e-16 -1.1584019516324405e-16" />
            <geometry>
                <mesh filename="meshes/2-clamp.stl" scale="0.001 0.001 0.001" />
            </geometry>
        </visual>
        <collision name="2-clamp_collision">
            <origin xyz="0.06839999551665468 -0.05204999999999996 -0.012000000223517826" rpy="-7.855721281318744e-17 8.881784197001016e-16 -1.1584019516324405e-16" />
            <geometry>
                <mesh filename="meshes/2-clamp.stl" scale="0.001 0.001 0.001" />
            </geometry>
        </collision>
    </link>
    <link name="2-servo">
        <inertial>
            <origin xyz="0.0133848172214125 -0.022668652600844476 4.48334644964632e-09" rpy="0.0 -0.0 0.0" />
            <mass value="0.303341237743085" />
            <inertia ixx="6.884216194161111e-05" iyy="4.4115613291402316e-05" izz="8.178619368153601e-05" ixy="9.243992458148683e-07" iyz="-2.168404344971009e-19" ixz="8.402566836762659e-19" />
        </inertial>
        <visual name="2-servo_visual">
            <origin xyz="0.0023499997764821565 -0.09680000000000012 -0.04294999551665474" rpy="-7.855721281318742e-17 1.5707963267948954 0" />
            <geometry>
                <mesh filename="meshes/2-servo.stl" scale="0.001 0.001 0.001" />
            </geometry>
        </visual>
        <collision name="2-servo_collision">
            <origin xyz="0.0023499997764821565 -0.09680000000000012 -0.04294999551665474" rpy="-7.855721281318742e-17 1.5707963267948954 0" />
            <geometry>
                <mesh filename="meshes/2-servo.stl" scale="0.001 0.001 0.001" />
            </geometry>
        </collision>
    </link>
    <link name="2-holder">
        <inertial>
            <origin xyz="-0.02324155945658018 8.85018176797292e-05 -0.011650988621288208" rpy="0.0 -0.0 0.0" />
            <mass value="0.32460683329419165" />
            <inertia ixx="0.00021745857967022915" iyy="0.0002559425379698605" izz="8.460393736434754e-05" ixy="1.4705050485426985e-07" iyz="-1.6269079107266083e-06" ixz="1.969093697167071e-05" />
        </inertial>
        <visual name="2-holder_visual">
            <origin xyz="0.014669775516654666 0.012000000223517722 -0.039700000000000034" rpy="1.5707963267948966 1.158401951632396e-16 -5.551115123125637e-17" />
            <geometry>
                <mesh filename="meshes/2-holder.stl" scale="0.001 0.001 0.001" />
            </geometry>
        </visual>
        <collision name="2-holder_collision">
            <origin xyz="0.014669775516654666 0.012000000223517722 -0.039700000000000034" rpy="1.5707963267948966 1.158401951632396e-16 -5.551115123125637e-17" />
            <geometry>
                <mesh filename="meshes/2-holder.stl" scale="0.001 0.001 0.001" />
            </geometry>
        </collision>
    </link>
    <link name="4-servo">
        <inertial>
            <origin xyz="-0.0226686526008381 -0.01338481766844729 -1.3410998533913698e-09" rpy="0.0 -0.0 0.0" />
            <mass value="0.303341237743085" />
            <inertia ixx="4.4115613291515615e-05" iyy="6.884216194150486e-05" izz="8.178619368142022e-05" ixy="-9.243992458312939e-07" iyz="2.656295322589486e-17" ixz="-5.0306980803327406e-17" />
        </inertial>
        <visual name="4-servo_visual">
            <origin xyz="0.019300000000009056 -0.0023500002235164936 -0.13905000134110426" rpy="1.5707963267949046 8.419475145046022e-16 -2.609024107869011e-15" />
            <geometry>
                <mesh filename="meshes/4-servo.stl" scale="0.001 0.001 0.001" />
            </geometry>
        </visual>
        <collision name="4-servo_collision">
            <origin xyz="0.019300000000009056 -0.0023500002235164936 -0.13905000134110426" rpy="1.5707963267949046 8.419475145046022e-16 -2.609024107869011e-15" />
            <geometry>
                <mesh filename="meshes/4-servo.stl" scale="0.001 0.001 0.001" />
            </geometry>
        </collision>
    </link>
    <link name="5-holder">
        <inertial>
            <origin xyz="0.025200986943076487 -0.00015906445619712884 -0.01026902702589766" rpy="0.0 -0.0 1.9446922743316064e-62" />
            <mass value="0.22663235669196308" />
            <inertia ixx="0.00013081580331984234" iyy="0.00020997897203484973" izz="0.0001161875623261095" ixy="7.533615649507608e-07" iyz="5.166496243413738e-07" ixz="-4.4235413830480164e-05" />
        </inertial>
        <visual name="5-holder_visual">
            <origin xyz="0.029999998658904303 0.1392500013411017 -0.00844999999999874" rpy="-3.141592653589786 3.3306690738753702e-15 4.1864152856486485e-16" />
            <geometry>
                <mesh filename="meshes/5-holder.stl" scale="0.001 0.001 0.001" />
            </geometry>
        </visual>
        <collision name="5-holder_collision">
            <origin xyz="0.029999998658904303 0.1392500013411017 -0.00844999999999874" rpy="-3.141592653589786 3.3306690738753702e-15 4.1864152856486485e-16" />
            <geometry>
                <mesh filename="meshes/5-holder.stl" scale="0.001 0.001 0.001" />
            </geometry>
        </collision>
    </link>
    <link name="5-clamp">
        <inertial>
            <origin xyz="0.026616332223443787 -0.025350001341104902 -4.483355517947985e-09" rpy="0.0 -0.0 0.0" />
            <mass value="0.09978554550837304" />
            <inertia ixx="2.89521955404385e-05" iyy="2.8802758876885458e-05" izz="4.5158254569147883e-05" ixy="-3.504683522559393e-17" iyz="8.066464163292153e-17" ixz="-2.813504637599884e-17" />
        </inertial>
        <visual name="5-clamp_visual">
            <origin xyz="0.01620000000000082 -0.1650000013411221 0.015770221341091357" rpy="1.7362303445243568e-14 1.5707963267948954 0" />
            <geometry>
                <mesh filename="meshes/5-clamp.stl" scale="0.001 0.001 0.001" />
            </geometry>
        </visual>
        <collision name="5-clamp_collision">
            <origin xyz="0.01620000000000082 -0.1650000013411221 0.015770221341091357" rpy="1.7362303445243568e-14 1.5707963267948954 0" />
            <geometry>
                <mesh filename="meshes/5-clamp.stl" scale="0.001 0.001 0.001" />
            </geometry>
        </collision>
    </link>
    <link name="5-servo">
        <inertial>
            <origin xyz="-0.013384812961574717 0.022668652153807988 -1.3411031929422279e-09" rpy="0.0 -3.9720831694007165e-93 0.0" />
            <mass value="0.3033412377430852" />
            <inertia ixx="6.884216194150312e-05" iyy="4.411561329124847e-05" izz="8.178619368153124e-05" ixy="9.243992457372936e-07" iyz="8.397145825900232e-17" ixz="-2.498001805406602e-16" />
        </inertial>
        <visual name="5-servo_visual">
            <origin xyz="-0.028749995516641143 0.027099999552964448 -0.14005000134112236" rpy="1.570796326794913 6.82626122840167e-16 -1.0547118733937622e-15" />
            <geometry>
                <mesh filename="meshes/5-servo.stl" scale="0.001 0.001 0.001" />
            </geometry>
        </visual>
        <collision name="5-servo_collision">
            <origin xyz="-0.028749995516641143 0.027099999552964448 -0.14005000134112236" rpy="1.570796326794913 6.82626122840167e-16 -1.0547118733937622e-15" />
            <geometry>
                <mesh filename="meshes/5-servo.stl" scale="0.001 0.001 0.001" />
            </geometry>
        </collision>
    </link>
    <link name="6-holder">
        <inertial>
            <origin xyz="-0.000620259399828007 0.022599496180974156 0.013086087178295323" rpy="3.068183415810975e-92 -0.0 0.0" />
            <mass value="0.11843555415743529" />
            <inertia ixx="4.1697596690029246e-05" iyy="2.17547368667418e-05" izz="4.958416643150061e-05" ixy="5.193143938311048e-07" iyz="-6.613169897994904e-06" ixz="1.5914304063328503e-07" />
        </inertial>
        <visual name="6-holder_visual">
            <origin xyz="0.13883488887593406 0.014100001564624876 -0.03436510842887326" rpy="1.5707963267949137 -1.570796326794895 0" />
            <geometry>
                <mesh filename="meshes/6-holder.stl" scale="0.001 0.001 0.001" />
            </geometry>
        </visual>
        <collision name="6-holder_collision">
            <origin xyz="0.13883488887593406 0.014100001564624876 -0.03436510842887326" rpy="1.5707963267949137 -1.570796326794895 0" />
            <geometry>
                <mesh filename="meshes/6-holder.stl" scale="0.001 0.001 0.001" />
            </geometry>
        </collision>
    </link>
    <link name="6-clamp">
        <inertial>
            <origin xyz="0.026616329171997605 -1.1175904290894323e-09 0.025349998875922212" rpy="0.0 -0.0 0.0" />
            <mass value="0.09978554550837294" />
            <inertia ixx="2.895219554050095e-05" iyy="4.51582545688391e-05" izz="2.8802758876780507e-05" ixy="1.734723475976807e-17" iyz="-3.04118709382184e-17" ixz="-1.0115606269289756e-16" />
        </inertial>
        <visual name="6-clamp_visual">
            <origin xyz="-0.046270228428885826 0.014699998435376784 0.16499999887595906" rpy="-1.570796326794886 4.99600361081174e-16 -2.680806523213026e-14" />
            <geometry>
                <mesh filename="meshes/6-clamp.stl" scale="0.001 0.001 0.001" />
            </geometry>
        </visual>
        <collision name="6-clamp_collision">
            <origin xyz="-0.046270228428885826 0.014699998435376784 0.16499999887595906" rpy="-1.570796326794886 4.99600361081174e-16 -2.680806523213026e-14" />
            <geometry>
                <mesh filename="meshes/6-clamp.stl" scale="0.001 0.001 0.001" />
            </geometry>
        </collision>
    </link>
    <link name="6-servo">
        <inertial>
            <origin xyz="-0.0226686552052567 1.1240793362787827e-09 0.013384816327338988" rpy="0.0 -0.0 0.0" />
            <mass value="0.3033412377430852" />
            <inertia ixx="4.411561329141153e-05" iyy="8.178619368123113e-05" izz="6.884216194048484e-05" ixy="3.2959746043559335e-16" iyz="1.102633609417758e-16" ixz="9.243992458735778e-07" />
        </inertial>
        <visual name="6-servo_visual">
            <origin xyz="-0.0918000026044378 -0.14004999887595984 0.03024999888241144" rpy="2.2982635136200886e-14 2.702317263721722e-14 1.4988010832435235e-15" />
            <geometry>
                <mesh filename="meshes/6-servo.stl" scale="0.001 0.001 0.001" />
            </geometry>
        </visual>
        <collision name="6-servo_collision">
            <origin xyz="-0.0918000026044378 -0.14004999887595984 0.03024999888241144" rpy="2.2982635136200886e-14 2.702317263721722e-14 1.4988010832435235e-15" />
            <geometry>
                <mesh filename="meshes/6-servo.stl" scale="0.001 0.001 0.001" />
            </geometry>
        </collision>
    </link>
    <link name="7-horn">
        <inertial>
            <origin xyz="0.028016893676572716 -0.02026136664877786 1.1296585067377407e-09" rpy="0.0 -0.0 0.0" />
            <mass value="0.28812146575896763" />
            <inertia ixx="9.648098395586939e-05" iyy="0.00011263347334324394" izz="0.00018954234620102706" ixy="1.9195329700461006e-06" iyz="-5.653879559433239e-15" ixz="4.505558158061861e-14" />
        </inertial>
        <visual name="7-horn_visual">
            <origin xyz="-0.07900000394551708 -0.03544999865888986 -0.13924999887592487" rpy="1.5707963267949032 -1.4988010832438895e-15 2.5641583126187996e-14" />
            <geometry>
                <mesh filename="meshes/7-horn.stl" scale="0.001 0.001 0.001" />
            </geometry>
        </visual>
        <collision name="7-horn_collision">
            <origin xyz="-0.07900000394551708 -0.03544999865888986 -0.13924999887592487" rpy="1.5707963267949032 -1.4988010832438895e-15 2.5641583126187996e-14" />
            <geometry>
                <mesh filename="meshes/7-horn.stl" scale="0.001 0.001 0.001" />
            </geometry>
        </collision>
    </link>
    <link name="1-holder">
        <inertial>
            <origin xyz="-0.021349999999999883 -0.041014448746961626 0.021574090412184478" rpy="0.0 -0.0 0.0" />
            <mass value="0.6280816514154953" />
            <inertia ixx="0.0005040491708915909" iyy="0.0009839230221836749" izz="0.0009513530034046948" ixy="-3.767602549387128e-18" iyz="0.00011962900425494654" ixz="7.386127300057499e-19" />
        </inertial>
        <visual name="1-holder_visual">
            <origin xyz="-0.0337 -0.019950000000000002 0.0165" rpy="-0.0 1.5707963267948966 0" />
            <geometry>
                <mesh filename="meshes/1-holder.stl" scale="0.001 0.001 0.001" />
            </geometry>
        </visual>
        <collision name="1-holder_collision">
            <origin xyz="-0.0337 -0.019950000000000002 0.0165" rpy="-0.0 1.5707963267948966 0" />
            <geometry>
                <mesh filename="meshes/1-holder.stl" scale="0.001 0.001 0.001" />
            </geometry>
        </collision>
    </link>
    <joint name="1-clamp_Rigid-1" type="fixed">
        <origin xyz="0.0165 0.019950000000000002 0.0337" rpy="-0.0 -1.5707963267948966 0" />
        <parent link="1-clamp" />
        <child link="1-holder" />
    </joint>
    <joint name="1-clamp_Rigid-2" type="fixed">
        <origin xyz="-0.0275 0.03395 0.012350000000000002" rpy="3.141592653589793 -0.0 0.0" />
        <parent link="1-clamp" />
        <child link="1-servo" />
    </joint>
    <joint name="1-servo_1-yaw" type="revolute">
        <origin xyz="0.013000000000000001 -0.005750000000000002 0.0" rpy="1.5707963267948966 -0.0 0.0" />
        <parent link="1-servo" />
        <child link="2-holder" />
        <axis xyz="0.0 0.0 1.0" />
        <limit lower="-1.570796" upper="1.570796" effort="1000000" velocity="1000000" />
    </joint>
    <joint name="2-holder_Rigid-4" type="fixed">
        <origin xyz="-0.05371022 0.0 0.0123" rpy="1.5707963267948966 4.3608013207788786e-33 6.162975822039155e-33" />
        <parent link="2-holder" />
        <child link="2-clamp" />
    </joint>
    <joint name="2-clamp_Rigid-5" type="fixed">
        <origin xyz="0.02535 0.044 -0.014000000000000002" rpy="1.7791258877055312e-34 -1.5707963267948966 0" />
        <parent link="2-clamp" />
        <child link="2-servo" />
    </joint>
    <joint name="3-holder_Rigid-7" type="fixed">
        <origin xyz="0.02416511 0.16658488999999999 -0.01790000000000004" rpy="-2.220446049250313e-16 1.972152263052531e-31 5.261630935975519e-31" />
        <parent link="3-holder" />
        <child link="3-clamp" />
    </joint>
    <joint name="3-clamp_Rigid-8" type="fixed">
        <origin xyz="0.044000000000000004 -0.02535 -0.013999999999999999" rpy="-5.470005157845276e-31 -1.5707963267948966 0" />
        <parent link="3-clamp" />
        <child link="3-servo" />
    </joint>
    <joint name="4-holder_Rigid-10" type="fixed">
        <origin xyz="0.11991510999999999 -0.026034889999999998 -0.017899999999999996" rpy="3.141592653589793 3.944304526105061e-31 9.04679294230822e-31" />
        <parent link="4-holder" />
        <child link="4-clamp" />
    </joint>
    <joint name="4-clamp_Rigid-11" type="fixed">
        <origin xyz="0.044000000000000004 -0.02535 0.013999999999999999" rpy="1.5707963267948966 3.944304526105059e-31 -3.257879004812441e-31" />
        <parent link="4-clamp" />
        <child link="4-servo" />
    </joint>
    <joint name="4-servo_4-pitch" type="revolute">
        <origin xyz="-0.013000000000000008 0.00575 0.0" rpy="-1.5707963267948966 4.721721744173088e-31 0.0" />
        <parent link="4-servo" />
        <child link="5-holder" />
        <axis xyz="-3.944304526105059e-31 7.395570986446986e-31 1.0" />
        <limit lower="-1.570796" upper="1.570796" effort="1000000" velocity="1000000" />
    </joint>
    <joint name="5-holder_Rigid-13" type="fixed">
        <origin xyz="0.04578022000000001 -0.025749999999999995 0.007850000000000001" rpy="3.141592653589793 1.5707963267948963 0" />
        <parent link="5-holder" />
        <child link="5-clamp" />
    </joint>
    <joint name="5-clamp_Rigid-14" type="fixed">
        <origin xyz="0.044000000000000004 -0.02535 -0.013999999999999986" rpy="-1.5707963267948966 1.5707963267948966 0" />
        <parent link="5-clamp" />
        <child link="5-servo" />
    </joint>
    <joint name="5-servo_5-roll" type="revolute">
        <origin xyz="0.0057500000000000285 0.013000000000000001 0.0" rpy="-1.5707963267948963 3.1554436208840472e-30 -1.5707963267948966" />
        <parent link="5-servo" />
        <child link="6-holder" />
        <axis xyz="0.0 2.2204460492502372e-16 1.0" />
        <limit lower="-1.570796" upper="1.570796" effort="1000000" velocity="1000000" />
    </joint>
    <joint name="6-holder_Rigid-16" type="fixed">
        <origin xyz="-0.026165110000000002 0.029350000000000022 0.011465119999999978" rpy="3.141592653589793 -1.5707963267948963 0" />
        <parent link="6-holder" />
        <child link="6-clamp" />
    </joint>
    <joint name="6-clamp_Rigid-17" type="fixed">
        <origin xyz="0.044000000000000025 -0.014000000000000021 0.02535" rpy="-1.5707963267948966 -1.2347103262258056e-30 1.9480294112644395e-60" />
        <parent link="6-clamp" />
        <child link="6-servo" />
    </joint>
    <joint name="6-servo_6-grip" type="revolute">
        <origin xyz="-0.013000000000000008 0.0 -0.005749999999999993" rpy="-1.5707963267948963 3.4702805965586234e-60 -2.1995516405939585e-30" />
        <parent link="6-servo" />
        <child link="7-horn" />
        <axis xyz="-0.0 1.0 -2.2204460492503136e-16" />
        <limit lower="-1.570796" upper="1.570796" effort="1000000" velocity="1000000" />
    </joint>
    <joint name="2-servo_2-pitch" type="revolute">
        <origin xyz="0.031150000000000004 -0.012999999999999989 0.0" rpy="2.220446049250313e-16 1.5707963267948966 0" />
        <parent link="2-servo" />
        <child link="3-holder" />
        <axis xyz="1.9721522630525295e-31 2.220446049250313e-16 1.0" />
        <limit lower="-1.570796" upper="1.570796" effort="1000000" velocity="1000000" />
    </joint>
    <joint name="3-servo_3-pitch" type="revolute">
        <origin xyz="0.031150000000000004 0.0 0.013000000000000003" rpy="2.2204460492503136e-16 1.5707963267948966 0" />
        <parent link="3-servo" />
        <child link="4-holder" />
        <axis xyz="3.944304526105059e-31 2.220446049250313e-16 1.0" />
        <limit lower="-1.570796" upper="1.570796" effort="1000000" velocity="1000000" />
    </joint>
</robot>